Workbook

Sheet Panduan Pengisian
A1: PANDUAN PENGISIAN TEMPLATE DATA COSTING RUMAH SAKIT
A2: Tujuan | B2: Mengumpulkan data biaya, pegawai, dan layanan rumah sakit untuk perhitungan unit cost per hari rawat (KRIS C, KRIS B, KRIS A, VIP, ICU), per kunjungan IGD, dan per layanan klinis.
A3: Siapa yang mengisi | B3: Satu tim per rumah sakit: bagian keuangan (LO dan biaya), SDM (pegawai), rekam medis atau SIMRS (volume), umum atau sarpras (luas lantai dan aset).
A4: Periode data | B4: Satu tahun penuh (1 Januari sampai 31 Desember). Semua sheet harus memakai tahun yang sama.
A5: Cara memakai | B5: Simpan salinan file dengan nama: Template_Costing_[NamaRS]_[Tahun].xlsx. Isi hanya sel berwarna krem. Sel abu muda berisi rumus dan terkunci. Isian kosong berarti belum diisi. Proteksi sheet tanpa password (Review, Unprotect Sheet) bila perlu membuka kunci.
A7: A. SIAPKAN DOKUMEN SUMBER
A8: Laporan Operasional (LO) | B8: LO tingkat satuan kerja untuk tahun data, lengkap pendapatan dan beban.
A9: Rincian biaya | B9: Buku besar atau laporan biaya: gaji, jasa pelayanan, persediaan, barang dan jasa, pemeliharaan, penyusutan.
A10: Daftar pegawai | B10: Daftar pegawai aktif per unit kerja dan per profesi pada akhir tahun data.
A11: Data SIMRS | B11: Kunjungan rawat jalan dan IGD, hari rawat, pasien pulang, dan volume penunjang (resep, tes, pemeriksaan).
A12: SK direktur dan sarpras | B12: Jumlah tempat tidur per kelas dan luas lantai setiap unit.
A13: Daftar aset | B13: Nilai perolehan alat dan gedung per unit untuk perhitungan penyusutan.
A15: B. URUTAN PENGISIAN
A16: Sheet 1 | B16: Panduan Pengisian: baca dari atas sampai bawah.
A17: Sheet 2 | B17: Data Dasar RS: identitas, SDM per profesi. Hasil lain terbaca otomatis.
A18: Sheet 3 | B18: Data Operasional: tempat tidur, hari rawat, pasien pulang, kunjungan, volume penunjang.
A19: Sheet 4 | B19: Data LO Lapkeu: pendapatan dan beban dari LO.
A20: Sheet 5 | B20: Costing Template: staf, luas lantai, dan biaya untuk 54 pusat biaya.
A21: Sheet 6 | B21: Rumus Perhitungan: hanya dibaca. Isi bobot pemakaian penunjang pada bagian 6. Hasil unit cost ada pada bagian 8.
A23: C. LANGKAH RINCI
A24: Langkah 1: Data Dasar RS | B24: Isi nama RS, tipe (A, B, C, D), kepemilikan, dan tahun data. Isi tabel SDM per profesi (baris 33 sampai 44) dengan jumlah orang. Jumlah SDM dokter, nakes, dan non nakes terisi otomatis. Isi identitas pengisi pada baris 64 sampai 70.
A25: Langkah 2: Tempat tidur | B25: Data Operasional kolom J baris 2 sampai 6: jumlah tempat tidur KRIS C, KRIS B, KRIS A, VIP, dan ICU. Contoh: SK direktur menyebut kelas 3 berjumlah 120 tempat tidur, tulis 120 pada KRIS C.
A26: Langkah 3: Hari rawat dan pasien pulang | B26: Data Operasional kolom D dan E baris 2 sampai 6: hari rawat JKN dan Non-JKN setahun per kelas. Kolom N: jumlah pasien pulang (hidup dan mati). BOR dan ALOS terhitung otomatis. Cek: BOR wajar 50 sampai 90 persen, ALOS 3 sampai 7 hari.
A27: Langkah 4: Kunjungan | B27: Data Operasional kolom B dan C baris 7 (IGD) dan baris 8 sampai 31 (24 layanan): kunjungan JKN dan Non-JKN setahun. Hemodialisis dimasukkan ke layanan Uronefro.
A28: Langkah 5: Volume penunjang | B28: Data Operasional blok Volume Penunjang Medis (kolom I sampai M): isi volume JKN dan Non-JKN untuk farmasi (lembar resep), radiologi (pemeriksaan), laboratorium (tes), dan seterusnya. Volume gizi terisi otomatis dari hari rawat.
A29: Langkah 6: Data LO Lapkeu | B29: Bagian I dan II: salin angka LO apa adanya. Bagian III: rincian beban untuk costing (gaji, jasa dokter, jasa lain, operasional lainnya, penyusutan alat, penyusutan gedung). Totalnya harus sama dengan total beban LO. Bagian IV: isi pendapatan fungsional JKN. Cek: selisih pada bagian III dan IV bernilai 0.
A30: Langkah 7: Costing Template bagian A (Overhead) | B30: Isi 12 pusat biaya penunjang umum: jumlah staf, biaya gaji, jasa medis, jasa medis lain, operasional, nilai alat, investasi gedung, dan luas lantai. Biaya gaji, jasa, dan operasional tiap unit dijumlahkan dari buku besar per unit kerja.
A31: Langkah 8: Costing Template bagian B (Penunjang medis) | B31: Isi 12 unit penunjang medis dengan cara yang sama seperti bagian A.
A32: Langkah 9: Costing Template bagian C (Layanan pasien) | B32: Isi 6 pusat biaya tetap (KRIS C, KRIS B, KRIS A, VIP, ICU, IGD) dan 24 layanan klinis. Kolom hari rawat, pasien pulang, dan kunjungan terbaca otomatis dari Data Operasional. Jumlah tempat tidur ditambahkan pada kolom I untuk kamar rawat inap.
A33: Langkah 10: Bobot pemakaian penunjang | B33: Rumus Perhitungan bagian 6: untuk setiap layanan, isi jumlah pemakaian tiap penunjang medis (contoh: jumlah resep, tes laboratorium, atau jam operasi yang dipakai layanan itu). Kosongkan bila tidak memakai. Gizi dan laundry terisi otomatis dari hari rawat.
A34: Langkah 11: Rekonsiliasi | B34: Costing Template sel S69 harus sama dengan total beban LO. Rumus Perhitungan bagian 10 menampilkan status BALANCE bila selisih paling banyak Rp1.000.
A35: Langkah 12: Baca hasil | B35: Rumus Perhitungan bagian 8: unit cost per pusat kamar dan layanan. Bagian 9: uji kewajaran BOR, ALOS, staf per tempat tidur. Status akhir harus SEMUA OK.
A37: D. MEMILIH DASAR ALOKASI (COSTING TEMPLATE KOLOM C)
A38: jumlah_staf | B38: Unit yang melayani seluruh pegawai: manajemen, komite, TI, pendidikan, bahan habis pakai non medis.
A39: luas_lantai | B39: Unit yang biayanya mengikuti luas bangunan: keamanan, kebersihan, listrik dan air, pajak, sewa.
A40: jumlah_kunjungan | B40: Unit yang melayani kunjungan rawat jalan dan IGD: parkir.
A41: jumlah_pasien | B41: Unit yang melayani pasien secara umum: customer service dan front office.
A42: hari_rawat | B42: Unit yang melayani pasien rawat inap: gizi, laundry, dan seluruh kamar rawat inap.
A44: E. PEMETAAN KELAS RAWAT KE PUSAT BIAYA
A45: Kelas 3 | B45: KRIS C
...

Sheet Data Dasar RS
A1: DATA DASAR RUMAH SAKIT | B1: NILAI | C1: Keterangan | D1: Definisi Operasional (DO) | E1: Aturan Validasi Isian | F1: Hasil Pemeriksaan
A2: Nama Rumah Sakit | C2: Nama Rumah Sakit | D2: Nama resmi rumah sakit sesuai izin operasional atau SK penetapan. Tulis lengkap tanpa singkatan. | E2: Wajib. Teks 5 sampai 100 karakter | F2: =IF(LEN(TRIM(B2))=0,"KOSONG: isi nama RS",IF(LEN(TRIM(B2))<5,"CEK: nama terlalu pendek","OK")) -> KOSONG: isi nama RS
A3: Tipe RS | C3: A, B, C, atau D. | D3: Klasifikasi RS menurut Kemenkes berdasarkan fasilitas dan kemampuan layanan. Tipe A paling lengkap, D paling dasar. | E3: Wajib. Pilih dari daftar: A, B, C, atau D. Harus sama dengan Costing Template sel K2. | F3: =IF(B3="","KOSONG: pilih tipe RS",IF(ISERROR(MATCH(B3,{"A","B","C","D"},0)),"CEK: pilih A, B, C, atau D",IF(AND('Costing Template'!K2<>"",'Costing Template'!K2<>B3),"CEK: beda dengan Costing Template K2","OK"))) -> KOSONG: pilih tipe RS
A4: Kepemilikan RS | C4: Pemerintah Pusat, Pemerintah Daerah, atau Swasta. | D4: Pihak yang memiliki dan menyelenggarakan RS (pemerintah pusat, pemerintah daerah, swasta, TNI/Polri, atau BUMN). | E4: Wajib. Pilih dari daftar. Harus sama dengan Costing Template sel N2. | F4: =IF(B4="","KOSONG: pilih kepemilikan",IF(AND('Costing Template'!N2<>"",'Costing Template'!N2<>B4),"CEK: beda dengan Costing Template N2","OK")) -> KOSONG: pilih kepemilikan
A5: Tahun Data | C5: Sama dengan tahun pada Costing Template. | D5: Tahun data keuangan dan layanan yang dipakai, yaitu 1 Januari sampai 31 Desember tahun tersebut. Seluruh sheet memakai tahun yang sama. | E5: Wajib. Bilangan bulat 4 digit antara 2000 dan 2100. Harus sama dengan Costing Template sel B2. Contoh: 2025. | F5: =IF(B5="","KOSONG: isi tahun data",IF(OR(NOT(ISNUMBER(B5)),B5<2000,B5>2100,B5<>INT(B5)),"CEK: isi tahun 4 digit",IF(AND('Costing Template'!B2<>"",'Costing Template'!B2<>B5),"CEK: beda dengan Costing Template B2","OK"))) -> KOSONG: isi tahun data
A7: BOR (%) | B7: =IFERROR('Data Operasional'!P7,"") | C7: Otomatis dari Data Operasional. | D7: BOR (Bed Occupancy Rate): persentase tempat tidur yang terpakai selama setahun. Rumus: hari rawat ÷ (tempat tidur × 365) × 100. | E7: Otomatis (terkunci). Jangan diisi. | F7: =IF(B7="","Menunggu: Data Operasional","OK") -> Menunggu: Data Operasional
A8: ALOS (hari) | B8: =IFERROR('Data Operasional'!O7,"") | C8: Otomatis dari Data Operasional. | D8: ALOS (Average Length of Stay): rata-rata lama pasien dirawat. Rumus: total hari rawat ÷ pasien pulang. | E8: Otomatis (terkunci). Jangan diisi. | F8: =IF(B8="","Menunggu: Data Operasional","OK") -> Menunggu: Data Operasional
A9: Jumlah Tempat Tidur | B9: =IFERROR('Data Operasional'!J7,"") -> 0 | C9: Otomatis dari Data Operasional. | D9: Total tempat tidur rawat inap semua kelas (KRIS C, B, A, VIP, ICU). | E9: Otomatis (terkunci). Jangan diisi. | F9: =IF(B9="","Menunggu: Data Operasional","OK") -> OK
A10: Lama Hari Rawat JKN | B10: =IFERROR('Data Operasional'!K7,"") -> 0 | C10: Otomatis. | D10: Total hari rawat pasien JKN setahun, semua kelas. | E10: Otomatis (terkunci). Jangan diisi. | F10: =IF(B10="","Menunggu: Data Operasional","OK") -> OK
A11: Lama Hari Rawat Non JKN | B11: =IFERROR('Data Operasional'!L7,"") -> 0 | C11: Otomatis. | D11: Total hari rawat pasien Non JKN setahun, semua kelas. | E11: Otomatis (terkunci). Jangan diisi. | F11: =IF(B11="","Menunggu: Data Operasional","OK") -> OK
A12: Jumlah SDM Dokter | B12: =IFERROR(SUM(B33:B34),"") -> 0 | C12: Otomatis dari tabel SDM per profesi. | D12: Jumlah dokter spesialis ditambah dokter umum (orang). | E12: Otomatis (terkunci). Jangan diisi. | F12: =IF(B12="","Menunggu: tabel SDM","OK") -> OK
A13: Jumlah SDM Nakes | B13: =IFERROR(SUM(B35:B42),"") -> 0 | C13: Otomatis dari tabel SDM per profesi. | D13: Jumlah tenaga kesehatan selain dokter: perawat, bidan, apoteker, analis, radiografer, terapis, ahli gizi, nakes lain (orang). | E13: Otomatis (terkunci). Jangan diisi. | F13: =IF(B13="","Menunggu: tabel SDM","OK") -> OK
A14: Jumlah SDM Non Nakes | B14: =IFERROR(B43,"") -> 0 | C14: Otomatis dari tabel SDM per profesi. | D14: Jumlah tenaga non-kesehatan: administrasi, keuangan, IT, keamanan, kebersihan, dan sejenisnya (orang). | E14: Otomatis (terkunci). Jangan diisi. | F14: =IF(B14="","Menunggu: tabel SDM","OK") -> OK
A15: Biaya Gaji | B15: =IFERROR('Data LO Lapkeu'!B27,"") -> 0 | C15: Dari Data LO Lapkeu bagian III. | D15: Gaji pokok dan tunjangan pegawai selama setahun (Rupiah). | E15: Otomatis (terkunci). Jangan diisi. | F15: =IF(B15="","Menunggu: Data LO Lapkeu","OK") -> OK
A16: Biaya Jasa/Remunerasi | B16: =IFERROR('Data LO Lapkeu'!B28+'Data LO Lapkeu'!B29,"") -> 0 | C16: Jasa dokter ditambah jasa staf lain. | D16: Jasa pelayanan dokter ditambah jasa pelayanan staf lain selama setahun (Rupiah). | E16: Otomatis (terkunci). Jangan diisi. | F16: =IF(B16="","Menunggu: Data LO Lapkeu","OK") -> OK
A17: Biaya Operasional Lainnya | B17: =IFERROR('Data LO Lapkeu'!B30,"") -> 0 | C17: Persediaan, barang dan jasa, pemeliharaan, perjalanan dinas, piutang. | D17: Biaya selain gaji, jasa, dan penyusutan: persediaan, barang dan jasa, pemeliharaan, perjalanan dinas, penyisihan piutang (Rupiah). | E17: Otomatis (terkunci). Jangan diisi. | F17: =IF(B17="","Menunggu: Data LO Lapkeu","OK") -> OK
A18: Biaya Penyusutan | B18: =IFERROR('Data LO Lapkeu'!B31+'Data LO Lapkeu'!B32,"") -> 0 | C18: Alat dan gedung. | D18: Penyusutan alat dan gedung selama setahun (Rupiah). | E18: Otomatis (terkunci). Jangan diisi. | F18: =IF(B18="","Menunggu: Data LO Lapkeu","OK") -> OK
A19: Pendapatan Fungsional JKN | B19: =IFERROR('Data LO Lapkeu'!B36,"") -> 0 | C19: Dari Data LO Lapkeu bagian IV. | D19: Pendapatan dari klaim JKN selama setahun (Rupiah). | E19: Otomatis (terkunci). Jangan diisi. | F19: =IF(B19="","Menunggu: Data LO Lapkeu","OK") -> OK
A20: Pendapatan Fungsional Non JKN | B20: =IFERROR('Data LO Lapkeu'!B37,"") -> 0 | C20: Dari Data LO Lapkeu bagian IV. | D20: Pendapatan jasa layanan dari pasien dan penjamin selain JKN (Rupiah). | E20: Otomatis (terkunci). Jangan diisi. | F20: =IF(B20="","Menunggu: Data LO Lapkeu","OK") -> OK
A21: Pendapatan Lainnya | B21: =IFERROR('Data LO Lapkeu'!B38,"") -> 0 | C21: Dari Data LO Lapkeu bagian IV. | D21: Pendapatan RS di luar jasa layanan pasien: sewa, parkir, kerja sama (Rupiah). | E21: Otomatis (terkunci). Jangan diisi. | F21: =IF(B21="","Menunggu: Data LO Lapkeu","OK") -> OK
A22: Subsidi/Pendanaan Pemerintah | B22: =IFERROR('Data LO Lapkeu'!B39,"") -> 0 | C22: APBN dan hibah. | D22: Dana dari pemerintah (alokasi APBN) dan hibah (Rupiah). | E22: Otomatis (terkunci). Jangan diisi. | F22: =IF(B22="","Menunggu: Data LO Lapkeu","OK") -> OK
A24: TEMPAT TIDUR PER KELAS | B24: JUMLAH | C24: Keterangan | D24: Definisi Operasional (DO) | E24: Aturan Validasi Isian | F24: Hasil Pemeriksaan
A25: Kamar Rawat Inap Standar (KRIS) C | B25: =IFERROR('Data Operasional'!J2,"") -> 0 | C25: =IFERROR("BOR "&TEXT('Data Operasional'!P2,"0.0")&"%, ALOS "&TEXT('Data Operasional'!O2,"0.0")&" hari","") -> BOR %, ALOS hari | D25: Jumlah tempat tidur KRIS C (kelas 3 ditambah ruang isolasi). | E25: Otomatis (terkunci). Jangan diisi. | F25: =IF(B25="","Menunggu: Data Operasional J2","OK") -> OK
A26: Kamar Rawat Inap Standar (KRIS) B | B26: =IFERROR('Data Operasional'!J3,"") -> 0 | C26: =IFERROR("BOR "&TEXT('Data Operasional'!P3,"0.0")&"%, ALOS "&TEXT('Data Operasional'!O3,"0.0")&" hari","") -> BOR %, ALOS hari | D26: Jumlah tempat tidur KRIS B (kelas 2). | E26: Otomatis (terkunci). Jangan diisi. | F26: =IF(B26="","Menunggu: Data Operasional J3","OK") -> OK
A27: Kamar Rawat Inap Standar (KRIS) A | B27: =IFERROR('Data Operasional'!J4,"") -> 0 | C27: =IFERROR("BOR "&TEXT('Data Operasional'!P4,"0.0")&"%, ALOS "&TEXT('Data Operasional'!O4,"0.0")&" hari","") -> BOR %, ALOS hari | D27: Jumlah tempat tidur KRIS A (kelas 1). | E27: Otomatis (terkunci). Jangan diisi. | F27: =IF(B27="","Menunggu: Data Operasional J4","OK") -> OK
A28: Kamar VIP/VVIP/Suite | B28: =IFERROR('Data Operasional'!J5,"") -> 0 | C28: =IFERROR("BOR "&TEXT('Data Operasional'!P5,"0.0")&"%, ALOS "&TEXT('Data Operasional'!O5,"0.0")&" hari","") -> BOR %, ALOS hari | D28: Jumlah tempat tidur kamar VIP, VVIP, dan Suite. | E28: Otomatis (terkunci). Jangan diisi. | F28: =IF(B28="","Menunggu: Data Operasional J5","OK") -> OK
A29: Kamar ICU/ICCU/NICU/PICU/HCU | B29: =IFERROR('Data Operasional'!J6,"") -> 0 | C29: =IFERROR("BOR "&TEXT('Data Operasional'!P6,"0.0")&"%, ALOS "&TEXT('Data Operasional'!O6,"0.0")&" hari","") -> BOR %, ALOS hari | D29: Jumlah tempat tidur ruang intensif (ICU, ICCU, NICU, PICU, HCU). | E29: Otomatis (terkunci). Jangan diisi. | F29: =IF(B29="","Menunggu: Data Operasional J6","OK") -> OK
A30: Total tempat tidur | B30: =IFERROR(SUM(B25:B29),"") -> 0 | D30: Total tempat tidur seluruh kelas. | E30: Otomatis (terkunci). Jangan diisi. | F30: =IF(B30="","Menunggu: Data Operasional",IF(B30=B9,"OK","CEK: total tidak sama dengan B9")) -> OK
A32: SDM PER PROFESI | B32: JUMLAH | C32: Keterangan | D32: Definisi Operasional (DO) | E32: Aturan Validasi Isian | F32: Hasil Pemeriksaan
A33: Dokter spesialis | C33: Dokter | D33: Jumlah dokter spesialis dan subspesialis (orang) yang aktif bertugas pada 31 Desember tahun data. | E33: Wajib. Bilangan bulat ≥ 0. Isi 0 bila tidak ada. Satu orang dihitung di satu baris saja. | F33: =IF(B33="","KOSONG: isi 0 bila tidak ada",IF(AND(ISNUMBER(B33),B33>=0,B33=INT(B33)),"OK","CEK: harus bilangan bulat ≥ 0")) -> KOSONG: isi 0 bila tidak ada
A34: Dokter umum | C34: Dokter | D34: Jumlah dokter umum (orang) yang aktif pada 31 Desember tahun data. Dokter gigi umum dihitung di baris ini. | E34: Wajib. Bilangan bulat ≥ 0. Isi 0 bila tidak ada. | F34: =IF(B34="","KOSONG: isi 0 bila tidak ada",IF(AND(ISNUMBER(B34),B34>=0,B34=INT(B34)),"OK","CEK: harus bilangan bulat ≥ 0")) -> KOSONG: isi 0 bila tidak ada
A35: Perawat | C35: Nakes | D35: Jumlah perawat vokasi dan ners (orang) yang aktif pada 31 Desember tahun data. | E35: Wajib. Bilangan bulat ≥ 0. | F35: =IF(B35="","KOSONG: isi 0 bila tidak ada",IF(AND(ISNUMBER(B35),B35>=0,B35=INT(B35)),"OK","CEK: harus bilangan bulat ≥ 0")) -> KOSONG: isi 0 bila tidak ada
A36: Bidan | C36: Nakes | D36: Jumlah bidan (orang) yang aktif pada 31 Desember tahun data. | E36: Wajib. Bilangan bulat ≥ 0. | F36: =IF(B36="","KOSONG: isi 0 bila tidak ada",IF(AND(ISNUMBER(B36),B36>=0,B36=INT(B36)),"OK","CEK: harus bilangan bulat ≥ 0")) -> KOSONG: isi 0 bila tidak ada
A37: Apoteker dan tenaga teknis kefarmasian | C37: Nakes | D37: Jumlah apoteker dan tenaga teknis kefarmasian (asisten apoteker), orang, pada 31 Desember tahun data. | E37: Wajib. Bilangan bulat ≥ 0. | F37: =IF(B37="","KOSONG: isi 0 bila tidak ada",IF(AND(ISNUMBER(B37),B37>=0,B37=INT(B37)),"OK","CEK: harus bilangan bulat ≥ 0")) -> KOSONG: isi 0 bila tidak ada
A38: Analis laboratorium | C38: Nakes | D38: Jumlah analis kesehatan atau ATLM di laboratorium dan bank darah (orang). | E38: Wajib. Bilangan bulat ≥ 0. | F38: =IF(B38="","KOSONG: isi 0 bila tidak ada",IF(AND(ISNUMBER(B38),B38>=0,B38=INT(B38)),"OK","CEK: harus bilangan bulat ≥ 0")) -> KOSONG: isi 0 bila tidak ada
A39: Radiografer | C39: Nakes | D39: Jumlah radiografer (orang). | E39: Wajib. Bilangan bulat ≥ 0. | F39: =IF(B39="","KOSONG: isi 0 bila tidak ada",IF(AND(ISNUMBER(B39),B39>=0,B39=INT(B39)),"OK","CEK: harus bilangan bulat ≥ 0")) -> KOSONG: isi 0 bila tidak ada
A40: Fisioterapis dan terapis lain | C40: Nakes | D40: Jumlah fisioterapis, terapis okupasi, terapis wicara, dan terapis lain (orang). | E40: Wajib. Bilangan bulat ≥ 0. | F40: =IF(B40="","KOSONG: isi 0 bila tidak ada",IF(AND(ISNUMBER(B40),B40>=0,B40=INT(B40)),"OK","CEK: harus bilangan bulat ≥ 0")) -> KOSONG: isi 0 bila tidak ada
A41: Ahli gizi | C41: Nakes | D41: Jumlah ahli gizi atau nutrisionis (orang). | E41: Wajib. Bilangan bulat ≥ 0. | F41: =IF(B41="","KOSONG: isi 0 bila tidak ada",IF(AND(ISNUMBER(B41),B41>=0,B41=INT(B41)),"OK","CEK: harus bilangan bulat ≥ 0")) -> KOSONG: isi 0 bila tidak ada
A42: Nakes lain (penata anestesi, perekam medis) | C42: Nakes | D42: Jumlah tenaga kesehatan lain yang tidak masuk baris di atas: penata anestesi, perekam medis, sanitarian, elektromedis (orang). | E42: Wajib. Bilangan bulat ≥ 0. | F42: =IF(B42="","KOSONG: isi 0 bila tidak ada",IF(AND(ISNUMBER(B42),B42>=0,B42=INT(B42)),"OK","CEK: harus bilangan bulat ≥ 0")) -> KOSONG: isi 0 bila tidak ada
A43: Tenaga non-kesehatan | C43: Non Nakes | D43: Jumlah pegawai non-kesehatan: administrasi, keuangan, IT, keamanan, kebersihan, dan sejenisnya (orang). | E43: Wajib. Bilangan bulat ≥ 0. | F43: =IF(B43="","KOSONG: isi 0 bila tidak ada",IF(AND(ISNUMBER(B43),B43>=0,B43=INT(B43)),"OK","CEK: harus bilangan bulat ≥ 0")) -> KOSONG: isi 0 bila tidak ada
...

Sheet Data Operasional
A1: DATA OPERASIONAL RS | B1: Kunjungan JKN | C1: Kunjungan Non-JKN | D1: Hari Rawat JKN | E1: Hari Rawat Non-JKN | F1: Total Kunjungan (Otomatis) | G1: Total Hari Rawat (Otomatis) | I1: STATISTIK RAWAT INAP PER KELAS | J1: Tempat Tidur | K1: Hari Rawat JKN | L1: Hari Rawat Non-JKN | M1: Total Hari Rawat | N1: Pasien Pulang | O1: ALOS (hari) | P1: BOR (%) | Q1: Status BOR | S1: HASIL PEMERIKSAAN: Kunjungan dan Hari Rawat (kolom B–E) | T1: HASIL PEMERIKSAAN: Statistik Rawat Inap (kolom J, N)
A2: Kamar Rawat Inap Standar (KRIS) C | F2: =IFERROR(IF(COUNT(B2:C2)<2,"",SUM(B2:C2)),"") | G2: =IFERROR(IF(COUNT(D2:E2)<2,"",SUM(D2:E2)),"") | I2: Kamar Rawat Inap Standar (KRIS) C | K2: =IFERROR(D2,"") -> 0 | L2: =IFERROR(E2,"") -> 0 | M2: =IFERROR(K2+L2,"") -> 0 | O2: =IFERROR(M2/N2,"") | P2: =IFERROR(M2/(J2*365)*100,"") | Q2: =IFERROR(IF(P2="","",IF(AND(P2>=40,P2<=90),"OK","CEK")),"") | S2: =IF(COUNTA(D2:E2)>COUNT(D2:E2),"CEK: ada isian bukan angka",IF(COUNT(D2:E2)=0,"KOSONG: isi hari rawat JKN dan Non-JKN (kolom D, E)",IF(COUNT(D2:E2)<2,"BELUM LENGKAP: isi D dan E (boleh 0)",IF(OR(D2<0,E2<0,D2<>INT(D2),E2<>INT(E2)),"CEK: harus bilangan bulat ≥ 0",IF(SUM(B2:C2)>0,"CEK: kunjungan (B, C) tidak diisi untuk kelas rawat inap",IF(AND(J2<>"",D2+E2>J2*365),"CEK: hari rawat melebihi tempat tidur × 365","OK")))))) -> KOSONG: isi hari rawat JKN dan Non-JKN (kolom D, E) | T2: =IF(COUNTA(J2,N2)>COUNT(J2,N2),"CEK: ada isian bukan angka",IF(COUNT(J2,N2)=0,"KOSONG: isi tempat tidur (J) dan pasien pulang (N)",IF(COUNT(J2,N2)<2,"BELUM LENGKAP: isi J dan N (boleh 0)",IF(OR(J2<0,N2<0,J2<>INT(J2),N2<>INT(N2)),"CEK: harus bilangan bulat ≥ 0",IF(AND(J2=0,N(M2)>0),"CEK: ada hari rawat tetapi tempat tidur 0",IF(AND(N2=0,N(M2)>0),"CEK: ada hari rawat tetapi pasien pulang 0",IF(Q2="CEK","CEK: BOR "&TEXT(P2,"0.0")&"% di luar 40–90%, periksa J dan D/E","OK"))))))) -> KOSONG: isi tempat tidur (J) dan pasien pulang (N)
A3: Kamar Rawat Inap Standar (KRIS) B | F3: =IFERROR(IF(COUNT(B3:C3)<2,"",SUM(B3:C3)),"") | G3: =IFERROR(IF(COUNT(D3:E3)<2,"",SUM(D3:E3)),"") | I3: Kamar Rawat Inap Standar (KRIS) B | K3: =IFERROR(D3,"") -> 0 | L3: =IFERROR(E3,"") -> 0 | M3: =IFERROR(K3+L3,"") -> 0 | O3: =IFERROR(M3/N3,"") | P3: =IFERROR(M3/(J3*365)*100,"") | Q3: =IFERROR(IF(P3="","",IF(AND(P3>=40,P3<=90),"OK","CEK")),"") | S3: =IF(COUNTA(D3:E3)>COUNT(D3:E3),"CEK: ada isian bukan angka",IF(COUNT(D3:E3)=0,"KOSONG: isi hari rawat JKN dan Non-JKN (kolom D, E)",IF(COUNT(D3:E3)<2,"BELUM LENGKAP: isi D dan E (boleh 0)",IF(OR(D3<0,E3<0,D3<>INT(D3),E3<>INT(E3)),"CEK: harus bilangan bulat ≥ 0",IF(SUM(B3:C3)>0,"CEK: kunjungan (B, C) tidak diisi untuk kelas rawat inap",IF(AND(J3<>"",D3+E3>J3*365),"CEK: hari rawat melebihi tempat tidur × 365","OK")))))) -> KOSONG: isi hari rawat JKN dan Non-JKN (kolom D, E) | T3: =IF(COUNTA(J3,N3)>COUNT(J3,N3),"CEK: ada isian bukan angka",IF(COUNT(J3,N3)=0,"KOSONG: isi tempat tidur (J) dan pasien pulang (N)",IF(COUNT(J3,N3)<2,"BELUM LENGKAP: isi J dan N (boleh 0)",IF(OR(J3<0,N3<0,J3<>INT(J3),N3<>INT(N3)),"CEK: harus bilangan bulat ≥ 0",IF(AND(J3=0,N(M3)>0),"CEK: ada hari rawat tetapi tempat tidur 0",IF(AND(N3=0,N(M3)>0),"CEK: ada hari rawat tetapi pasien pulang 0",IF(Q3="CEK","CEK: BOR "&TEXT(P3,"0.0")&"% di luar 40–90%, periksa J dan D/E","OK"))))))) -> KOSONG: isi tempat tidur (J) dan pasien pulang (N)
A4: Kamar Rawat Inap Standar (KRIS) A | F4: =IFERROR(IF(COUNT(B4:C4)<2,"",SUM(B4:C4)),"") | G4: =IFERROR(IF(COUNT(D4:E4)<2,"",SUM(D4:E4)),"") | I4: Kamar Rawat Inap Standar (KRIS) A | K4: =IFERROR(D4,"") -> 0 | L4: =IFERROR(E4,"") -> 0 | M4: =IFERROR(K4+L4,"") -> 0 | O4: =IFERROR(M4/N4,"") | P4: =IFERROR(M4/(J4*365)*100,"") | Q4: =IFERROR(IF(P4="","",IF(AND(P4>=40,P4<=90),"OK","CEK")),"") | S4: =IF(COUNTA(D4:E4)>COUNT(D4:E4),"CEK: ada isian bukan angka",IF(COUNT(D4:E4)=0,"KOSONG: isi hari rawat JKN dan Non-JKN (kolom D, E)",IF(COUNT(D4:E4)<2,"BELUM LENGKAP: isi D dan E (boleh 0)",IF(OR(D4<0,E4<0,D4<>INT(D4),E4<>INT(E4)),"CEK: harus bilangan bulat ≥ 0",IF(SUM(B4:C4)>0,"CEK: kunjungan (B, C) tidak diisi untuk kelas rawat inap",IF(AND(J4<>"",D4+E4>J4*365),"CEK: hari rawat melebihi tempat tidur × 365","OK")))))) -> KOSONG: isi hari rawat JKN dan Non-JKN (kolom D, E) | T4: =IF(COUNTA(J4,N4)>COUNT(J4,N4),"CEK: ada isian bukan angka",IF(COUNT(J4,N4)=0,"KOSONG: isi tempat tidur (J) dan pasien pulang (N)",IF(COUNT(J4,N4)<2,"BELUM LENGKAP: isi J dan N (boleh 0)",IF(OR(J4<0,N4<0,J4<>INT(J4),N4<>INT(N4)),"CEK: harus bilangan bulat ≥ 0",IF(AND(J4=0,N(M4)>0),"CEK: ada hari rawat tetapi tempat tidur 0",IF(AND(N4=0,N(M4)>0),"CEK: ada hari rawat tetapi pasien pulang 0",IF(Q4="CEK","CEK: BOR "&TEXT(P4,"0.0")&"% di luar 40–90%, periksa J dan D/E","OK"))))))) -> KOSONG: isi tempat tidur (J) dan pasien pulang (N)
A5: Kamar VIP/VVIP/Suite | F5: =IFERROR(IF(COUNT(B5:C5)<2,"",SUM(B5:C5)),"") | G5: =IFERROR(IF(COUNT(D5:E5)<2,"",SUM(D5:E5)),"") | I5: Kamar VIP/VVIP/Suite | K5: =IFERROR(D5,"") -> 0 | L5: =IFERROR(E5,"") -> 0 | M5: =IFERROR(K5+L5,"") -> 0 | O5: =IFERROR(M5/N5,"") | P5: =IFERROR(M5/(J5*365)*100,"") | Q5: =IFERROR(IF(P5="","",IF(AND(P5>=40,P5<=90),"OK","CEK")),"") | S5: =IF(COUNTA(D5:E5)>COUNT(D5:E5),"CEK: ada isian bukan angka",IF(COUNT(D5:E5)=0,"KOSONG: isi hari rawat JKN dan Non-JKN (kolom D, E)",IF(COUNT(D5:E5)<2,"BELUM LENGKAP: isi D dan E (boleh 0)",IF(OR(D5<0,E5<0,D5<>INT(D5),E5<>INT(E5)),"CEK: harus bilangan bulat ≥ 0",IF(SUM(B5:C5)>0,"CEK: kunjungan (B, C) tidak diisi untuk kelas rawat inap",IF(AND(J5<>"",D5+E5>J5*365),"CEK: hari rawat melebihi tempat tidur × 365","OK")))))) -> KOSONG: isi hari rawat JKN dan Non-JKN (kolom D, E) | T5: =IF(COUNTA(J5,N5)>COUNT(J5,N5),"CEK: ada isian bukan angka",IF(COUNT(J5,N5)=0,"KOSONG: isi tempat tidur (J) dan pasien pulang (N)",IF(COUNT(J5,N5)<2,"BELUM LENGKAP: isi J dan N (boleh 0)",IF(OR(J5<0,N5<0,J5<>INT(J5),N5<>INT(N5)),"CEK: harus bilangan bulat ≥ 0",IF(AND(J5=0,N(M5)>0),"CEK: ada hari rawat tetapi tempat tidur 0",IF(AND(N5=0,N(M5)>0),"CEK: ada hari rawat tetapi pasien pulang 0",IF(Q5="CEK","CEK: BOR "&TEXT(P5,"0.0")&"% di luar 40–90%, periksa J dan D/E","OK"))))))) -> KOSONG: isi tempat tidur (J) dan pasien pulang (N)
A6: Kamar ICU/ICCU/NICU/PICU/HCU | F6: =IFERROR(IF(COUNT(B6:C6)<2,"",SUM(B6:C6)),"") | G6: =IFERROR(IF(COUNT(D6:E6)<2,"",SUM(D6:E6)),"") | I6: Kamar ICU/ICCU/NICU/PICU/HCU | K6: =IFERROR(D6,"") -> 0 | L6: =IFERROR(E6,"") -> 0 | M6: =IFERROR(K6+L6,"") -> 0 | O6: =IFERROR(M6/N6,"") | P6: =IFERROR(M6/(J6*365)*100,"") | Q6: =IFERROR(IF(P6="","",IF(AND(P6>=40,P6<=90),"OK","CEK")),"") | S6: =IF(COUNTA(D6:E6)>COUNT(D6:E6),"CEK: ada isian bukan angka",IF(COUNT(D6:E6)=0,"KOSONG: isi hari rawat JKN dan Non-JKN (kolom D, E)",IF(COUNT(D6:E6)<2,"BELUM LENGKAP: isi D dan E (boleh 0)",IF(OR(D6<0,E6<0,D6<>INT(D6),E6<>INT(E6)),"CEK: harus bilangan bulat ≥ 0",IF(SUM(B6:C6)>0,"CEK: kunjungan (B, C) tidak diisi untuk kelas rawat inap",IF(AND(J6<>"",D6+E6>J6*365),"CEK: hari rawat melebihi tempat tidur × 365","OK")))))) -> KOSONG: isi hari rawat JKN dan Non-JKN (kolom D, E) | T6: =IF(COUNTA(J6,N6)>COUNT(J6,N6),"CEK: ada isian bukan angka",IF(COUNT(J6,N6)=0,"KOSONG: isi tempat tidur (J) dan pasien pulang (N)",IF(COUNT(J6,N6)<2,"BELUM LENGKAP: isi J dan N (boleh 0)",IF(OR(J6<0,N6<0,J6<>INT(J6),N6<>INT(N6)),"CEK: harus bilangan bulat ≥ 0",IF(AND(J6=0,N(M6)>0),"CEK: ada hari rawat tetapi tempat tidur 0",IF(AND(N6=0,N(M6)>0),"CEK: ada hari rawat tetapi pasien pulang 0",IF(Q6="CEK","CEK: BOR "&TEXT(P6,"0.0")&"% di luar 40–90%, periksa J dan D/E","OK"))))))) -> KOSONG: isi tempat tidur (J) dan pasien pulang (N)
A7: Instalasi Gawat Darurat (IGD) | F7: =IFERROR(IF(COUNT(B7:C7)<2,"",SUM(B7:C7)),"") | G7: =IFERROR(IF(COUNT(D7:E7)<2,"",SUM(D7:E7)),"") | I7: TOTAL RS | J7: =IFERROR(SUM(J2:J6),"") -> 0 | K7: =IFERROR(SUM(K2:K6),"") -> 0 | L7: =IFERROR(SUM(L2:L6),"") -> 0 | M7: =IFERROR(SUM(M2:M6),"") -> 0 | N7: =IFERROR(SUM(N2:N6),"") -> 0 | O7: =IFERROR(M7/N7,"") | P7: =IFERROR(M7/(J7*365)*100,"") | Q7: =IFERROR(IF(P7="","",IF(AND(P7>=50,P7<=85),"OK","CEK")),"") | S7: =IF(COUNTA(B7:C7)>COUNT(B7:C7),"CEK: ada isian bukan angka",IF(COUNT(B7:C7)=0,"KOSONG: isi kunjungan JKN dan Non-JKN (kolom B, C)",IF(COUNT(B7:C7)<2,"BELUM LENGKAP: isi B dan C (boleh 0)",IF(OR(B7<0,C7<0,B7<>INT(B7),C7<>INT(C7)),"CEK: harus bilangan bulat ≥ 0",IF(SUM(D7:E7)>0,"CEK: hari rawat hanya diisi di baris 2–6 (rawat inap)","OK"))))) -> KOSONG: isi kunjungan JKN dan Non-JKN (kolom B, C) | T7: =IF(Q7="","Menunggu: data tempat tidur dan hari rawat",IF(Q7="OK","OK: BOR total RS wajar (50–85%)","CEK: BOR total RS "&TEXT(P7,"0.0")&"% di luar 50–85%")) -> Menunggu: data tempat tidur dan hari rawat
A8: Neoplasma dan Myeloproliferative | F8: =IFERROR(IF(COUNT(B8:C8)<2,"",SUM(B8:C8)),"") | G8: =IFERROR(IF(COUNT(D8:E8)<2,"",SUM(D8:E8)),"") | I8: BOR = hari rawat ÷ (tempat tidur × 365) × 100. ALOS = hari rawat ÷ pasien pulang. Rentang wajar BOR 40 sampai 90 per kelas, total RS 50 sampai 85. | S8: =IF(COUNTA(B8:C8)>COUNT(B8:C8),"CEK: ada isian bukan angka",IF(COUNT(B8:C8)=0,"KOSONG: isi kunjungan JKN dan Non-JKN (kolom B, C)",IF(COUNT(B8:C8)<2,"BELUM LENGKAP: isi B dan C (boleh 0)",IF(OR(B8<0,C8<0,B8<>INT(B8),C8<>INT(C8)),"CEK: harus bilangan bulat ≥ 0",IF(SUM(D8:E8)>0,"CEK: hari rawat hanya diisi di baris 2–6 (rawat inap)","OK"))))) -> KOSONG: isi kunjungan JKN dan Non-JKN (kolom B, C)
A9: Jantung dan Pembuluh Darah | F9: =IFERROR(IF(COUNT(B9:C9)<2,"",SUM(B9:C9)),"") | G9: =IFERROR(IF(COUNT(D9:E9)<2,"",SUM(D9:E9)),"") | S9: =IF(COUNTA(B9:C9)>COUNT(B9:C9),"CEK: ada isian bukan angka",IF(COUNT(B9:C9)=0,"KOSONG: isi kunjungan JKN dan Non-JKN (kolom B, C)",IF(COUNT(B9:C9)<2,"BELUM LENGKAP: isi B dan C (boleh 0)",IF(OR(B9<0,C9<0,B9<>INT(B9),C9<>INT(C9)),"CEK: harus bilangan bulat ≥ 0",IF(SUM(D9:E9)>0,"CEK: hari rawat hanya diisi di baris 2–6 (rawat inap)","OK"))))) -> KOSONG: isi kunjungan JKN dan Non-JKN (kolom B, C)
A10: Saraf / Neuroscience | F10: =IFERROR(IF(COUNT(B10:C10)<2,"",SUM(B10:C10)),"") | G10: =IFERROR(IF(COUNT(D10:E10)<2,"",SUM(D10:E10)),"") | I10: VOLUME PENUNJANG MEDIS (SETAHUN) | J10: Satuan | K10: Volume JKN | L10: Volume Non-JKN | M10: Total Volume | S10: =IF(COUNTA(B10:C10)>COUNT(B10:C10),"CEK: ada isian bukan angka",IF(COUNT(B10:C10)=0,"KOSONG: isi kunjungan JKN dan Non-JKN (kolom B, C)",IF(COUNT(B10:C10)<2,"BELUM LENGKAP: isi B dan C (boleh 0)",IF(OR(B10<0,C10<0,B10<>INT(B10),C10<>INT(C10)),"CEK: harus bilangan bulat ≥ 0",IF(SUM(D10:E10)>0,"CEK: hari rawat hanya diisi di baris 2–6 (rawat inap)","OK"))))) -> KOSONG: isi kunjungan JKN dan Non-JKN (kolom B, C) | T10: HASIL PEMERIKSAAN: Volume Penunjang (kolom K, L)
A11: Kesehatan Ibu dan Ginekologi | F11: =IFERROR(IF(COUNT(B11:C11)<2,"",SUM(B11:C11)),"") | G11: =IFERROR(IF(COUNT(D11:E11)<2,"",SUM(D11:E11)),"") | I11: Farmasi | J11: lembar resep | M11: =IFERROR(K11+L11,"") -> 0 | S11: =IF(COUNTA(B11:C11)>COUNT(B11:C11),"CEK: ada isian bukan angka",IF(COUNT(B11:C11)=0,"KOSONG: isi kunjungan JKN dan Non-JKN (kolom B, C)",IF(COUNT(B11:C11)<2,"BELUM LENGKAP: isi B dan C (boleh 0)",IF(OR(B11<0,C11<0,B11<>INT(B11),C11<>INT(C11)),"CEK: harus bilangan bulat ≥ 0",IF(SUM(D11:E11)>0,"CEK: hari rawat hanya diisi di baris 2–6 (rawat inap)","OK"))))) -> KOSONG: isi kunjungan JKN dan Non-JKN (kolom B, C) | T11: =IF(COUNTA(K11:L11)>COUNT(K11:L11),"CEK: ada isian bukan angka",IF(COUNT(K11:L11)=0,"KOSONG: isi volume JKN (K) dan Non-JKN (L)",IF(COUNT(K11:L11)<2,"BELUM LENGKAP: isi K dan L (boleh 0)",IF(OR(K11<0,L11<0,K11<>INT(K11),L11<>INT(L11)),"CEK: harus bilangan bulat ≥ 0","OK")))) -> KOSONG: isi volume JKN (K) dan Non-JKN (L)
A12: Kesehatan Neonatus | F12: =IFERROR(IF(COUNT(B12:C12)<2,"",SUM(B12:C12)),"") | G12: =IFERROR(IF(COUNT(D12:E12)<2,"",SUM(D12:E12)),"") | I12: Radiologi | J12: pemeriksaan | M12: =IFERROR(K12+L12,"") -> 0 | S12: =IF(COUNTA(B12:C12)>COUNT(B12:C12),"CEK: ada isian bukan angka",IF(COUNT(B12:C12)=0,"KOSONG: isi kunjungan JKN dan Non-JKN (kolom B, C)",IF(COUNT(B12:C12)<2,"BELUM LENGKAP: isi B dan C (boleh 0)",IF(OR(B12<0,C12<0,B12<>INT(B12),C12<>INT(C12)),"CEK: harus bilangan bulat ≥ 0",IF(SUM(D12:E12)>0,"CEK: hari rawat hanya diisi di baris 2–6 (rawat inap)","OK"))))) -> KOSONG: isi kunjungan JKN dan Non-JKN (kolom B, C) | T12: =IF(COUNTA(K12:L12)>COUNT(K12:L12),"CEK: ada isian bukan angka",IF(COUNT(K12:L12)=0,"KOSONG: isi volume JKN (K) dan Non-JKN (L)",IF(COUNT(K12:L12)<2,"BELUM LENGKAP: isi K dan L (boleh 0)",IF(OR(K12<0,L12<0,K12<>INT(K12),L12<>INT(L12)),"CEK: harus bilangan bulat ≥ 0","OK")))) -> KOSONG: isi volume JKN (K) dan Non-JKN (L)
A13: Sistem Pencernaan dan Hepatobiliar | F13: =IFERROR(IF(COUNT(B13:C13)<2,"",SUM(B13:C13)),"") | G13: =IFERROR(IF(COUNT(D13:E13)<2,"",SUM(D13:E13)),"") | I13: Laboratorium | J13: tes | M13: =IFERROR(K13+L13,"") -> 0 | S13: =IF(COUNTA(B13:C13)>COUNT(B13:C13),"CEK: ada isian bukan angka",IF(COUNT(B13:C13)=0,"KOSONG: isi kunjungan JKN dan Non-JKN (kolom B, C)",IF(COUNT(B13:C13)<2,"BELUM LENGKAP: isi B dan C (boleh 0)",IF(OR(B13<0,C13<0,B13<>INT(B13),C13<>INT(C13)),"CEK: harus bilangan bulat ≥ 0",IF(SUM(D13:E13)>0,"CEK: hari rawat hanya diisi di baris 2–6 (rawat inap)","OK"))))) -> KOSONG: isi kunjungan JKN dan Non-JKN (kolom B, C) | T13: =IF(COUNTA(K13:L13)>COUNT(K13:L13),"CEK: ada isian bukan angka",IF(COUNT(K13:L13)=0,"KOSONG: isi volume JKN (K) dan Non-JKN (L)",IF(COUNT(K13:L13)<2,"BELUM LENGKAP: isi K dan L (boleh 0)",IF(OR(K13<0,L13<0,K13<>INT(K13),L13<>INT(L13)),"CEK: harus bilangan bulat ≥ 0","OK")))) -> KOSONG: isi volume JKN (K) dan Non-JKN (L)
A14: Uronefro (Urologi dan Nefrologi) | F14: =IFERROR(IF(COUNT(B14:C14)<2,"",SUM(B14:C14)),"") | G14: =IFERROR(IF(COUNT(D14:E14)<2,"",SUM(D14:E14)),"") | I14: Rehabilitasi Medik | J14: sesi terapi | M14: =IFERROR(K14+L14,"") -> 0 | S14: =IF(COUNTA(B14:C14)>COUNT(B14:C14),"CEK: ada isian bukan angka",IF(COUNT(B14:C14)=0,"KOSONG: isi kunjungan JKN dan Non-JKN (kolom B, C)",IF(COUNT(B14:C14)<2,"BELUM LENGKAP: isi B dan C (boleh 0)",IF(OR(B14<0,C14<0,B14<>INT(B14),C14<>INT(C14)),"CEK: harus bilangan bulat ≥ 0",IF(SUM(D14:E14)>0,"CEK: hari rawat hanya diisi di baris 2–6 (rawat inap)","OK"))))) -> KOSONG: isi kunjungan JKN dan Non-JKN (kolom B, C) | T14: =IF(COUNTA(K14:L14)>COUNT(K14:L14),"CEK: ada isian bukan angka",IF(COUNT(K14:L14)=0,"KOSONG: isi volume JKN (K) dan Non-JKN (L)",IF(COUNT(K14:L14)<2,"BELUM LENGKAP: isi K dan L (boleh 0)",IF(OR(K14<0,L14<0,K14<>INT(K14),L14<>INT(L14)),"CEK: harus bilangan bulat ≥ 0","OK")))) -> KOSONG: isi volume JKN (K) dan Non-JKN (L)
A15: Musculoskeletal dan Jaringan Lunak | F15: =IFERROR(IF(COUNT(B15:C15)<2,"",SUM(B15:C15)),"") | G15: =IFERROR(IF(COUNT(D15:E15)<2,"",SUM(D15:E15)),"") | I15: Rehabilitasi Psikososial | J15: pasien | M15: =IFERROR(K15+L15,"") -> 0 | S15: =IF(COUNTA(B15:C15)>COUNT(B15:C15),"CEK: ada isian bukan angka",IF(COUNT(B15:C15)=0,"KOSONG: isi kunjungan JKN dan Non-JKN (kolom B, C)",IF(COUNT(B15:C15)<2,"BELUM LENGKAP: isi B dan C (boleh 0)",IF(OR(B15<0,C15<0,B15<>INT(B15),C15<>INT(C15)),"CEK: harus bilangan bulat ≥ 0",IF(SUM(D15:E15)>0,"CEK: hari rawat hanya diisi di baris 2–6 (rawat inap)","OK"))))) -> KOSONG: isi kunjungan JKN dan Non-JKN (kolom B, C) | T15: =IF(COUNTA(K15:L15)>COUNT(K15:L15),"CEK: ada isian bukan angka",IF(COUNT(K15:L15)=0,"KOSONG: isi volume JKN (K) dan Non-JKN (L)",IF(COUNT(K15:L15)<2,"BELUM LENGKAP: isi K dan L (boleh 0)",IF(OR(K15<0,L15<0,K15<>INT(K15),L15<>INT(L15)),"CEK: harus bilangan bulat ≥ 0","OK")))) -> KOSONG: isi volume JKN (K) dan Non-JKN (L)
A16: Rekonstruksi dan Estetika | F16: =IFERROR(IF(COUNT(B16:C16)<2,"",SUM(B16:C16)),"") | G16: =IFERROR(IF(COUNT(D16:E16)<2,"",SUM(D16:E16)),"") | I16: Instalasi Bedah Sentral (IBS) | J16: jam operasi | M16: =IFERROR(K16+L16,"") -> 0 | S16: =IF(COUNTA(B16:C16)>COUNT(B16:C16),"CEK: ada isian bukan angka",IF(COUNT(B16:C16)=0,"KOSONG: isi kunjungan JKN dan Non-JKN (kolom B, C)",IF(COUNT(B16:C16)<2,"BELUM LENGKAP: isi B dan C (boleh 0)",IF(OR(B16<0,C16<0,B16<>INT(B16),C16<>INT(C16)),"CEK: harus bilangan bulat ≥ 0",IF(SUM(D16:E16)>0,"CEK: hari rawat hanya diisi di baris 2–6 (rawat inap)","OK"))))) -> KOSONG: isi kunjungan JKN dan Non-JKN (kolom B, C) | T16: =IF(COUNTA(K16:L16)>COUNT(K16:L16),"CEK: ada isian bukan angka",IF(COUNT(K16:L16)=0,"KOSONG: isi volume JKN (K) dan Non-JKN (L)",IF(COUNT(K16:L16)<2,"BELUM LENGKAP: isi K dan L (boleh 0)",IF(OR(K16<0,L16<0),"CEK: harus angka ≥ 0","OK")))) -> KOSONG: isi volume JKN (K) dan Non-JKN (L)
A17: Trauma | F17: =IFERROR(IF(COUNT(B17:C17)<2,"",SUM(B17:C17)),"") | G17: =IFERROR(IF(COUNT(D17:E17)<2,"",SUM(D17:E17)),"") | I17: Instalasi Gizi | J17: hari rawat | K17: =IFERROR(D32,"") -> 0 | L17: =IFERROR(E32,"") -> 0 | M17: =IFERROR(K17+L17,"") -> 0 | S17: =IF(COUNTA(B17:C17)>COUNT(B17:C17),"CEK: ada isian bukan angka",IF(COUNT(B17:C17)=0,"KOSONG: isi kunjungan JKN dan Non-JKN (kolom B, C)",IF(COUNT(B17:C17)<2,"BELUM LENGKAP: isi B dan C (boleh 0)",IF(OR(B17<0,C17<0,B17<>INT(B17),C17<>INT(C17)),"CEK: harus bilangan bulat ≥ 0",IF(SUM(D17:E17)>0,"CEK: hari rawat hanya diisi di baris 2–6 (rawat inap)","OK"))))) -> KOSONG: isi kunjungan JKN dan Non-JKN (kolom B, C) | T17: OK: otomatis dari total hari rawat (tidak diisi)
A18: Paru | F18: =IFERROR(IF(COUNT(B18:C18)<2,"",SUM(B18:C18)),"") | G18: =IFERROR(IF(COUNT(D18:E18)<2,"",SUM(D18:E18)),"") | I18: Laundry Rumah Sakit | J18: kg linen | M18: =IFERROR(K18+L18,"") -> 0 | S18: =IF(COUNTA(B18:C18)>COUNT(B18:C18),"CEK: ada isian bukan angka",IF(COUNT(B18:C18)=0,"KOSONG: isi kunjungan JKN dan Non-JKN (kolom B, C)",IF(COUNT(B18:C18)<2,"BELUM LENGKAP: isi B dan C (boleh 0)",IF(OR(B18<0,C18<0,B18<>INT(B18),C18<>INT(C18)),"CEK: harus bilangan bulat ≥ 0",IF(SUM(D18:E18)>0,"CEK: hari rawat hanya diisi di baris 2–6 (rawat inap)","OK"))))) -> KOSONG: isi kunjungan JKN dan Non-JKN (kolom B, C) | T18: =IF(COUNTA(K18:L18)>COUNT(K18:L18),"CEK: ada isian bukan angka",IF(COUNT(K18:L18)=0,"KOSONG: isi volume JKN (K) dan Non-JKN (L)",IF(COUNT(K18:L18)<2,"BELUM LENGKAP: isi K dan L (boleh 0)",IF(OR(K18<0,L18<0),"CEK: harus angka ≥ 0","OK")))) -> KOSONG: isi volume JKN (K) dan Non-JKN (L)
A19: THT (Telinga, Hidung, Tenggorokan) | F19: =IFERROR(IF(COUNT(B19:C19)<2,"",SUM(B19:C19)),"") | G19: =IFERROR(IF(COUNT(D19:E19)<2,"",SUM(D19:E19)),"") | I19: Unit Sterilisasi Alat (CSSD) | J19: paket steril | M19: =IFERROR(K19+L19,"") -> 0 | S19: =IF(COUNTA(B19:C19)>COUNT(B19:C19),"CEK: ada isian bukan angka",IF(COUNT(B19:C19)=0,"KOSONG: isi kunjungan JKN dan Non-JKN (kolom B, C)",IF(COUNT(B19:C19)<2,"BELUM LENGKAP: isi B dan C (boleh 0)",IF(OR(B19<0,C19<0,B19<>INT(B19),C19<>INT(C19)),"CEK: harus bilangan bulat ≥ 0",IF(SUM(D19:E19)>0,"CEK: hari rawat hanya diisi di baris 2–6 (rawat inap)","OK"))))) -> KOSONG: isi kunjungan JKN dan Non-JKN (kolom B, C) | T19: =IF(COUNTA(K19:L19)>COUNT(K19:L19),"CEK: ada isian bukan angka",IF(COUNT(K19:L19)=0,"KOSONG: isi volume JKN (K) dan Non-JKN (L)",IF(COUNT(K19:L19)<2,"BELUM LENGKAP: isi K dan L (boleh 0)",IF(OR(K19<0,L19<0,K19<>INT(K19),L19<>INT(L19)),"CEK: harus bilangan bulat ≥ 0","OK")))) -> KOSONG: isi volume JKN (K) dan Non-JKN (L)
A20: Mata | F20: =IFERROR(IF(COUNT(B20:C20)<2,"",SUM(B20:C20)),"") | G20: =IFERROR(IF(COUNT(D20:E20)<2,"",SUM(D20:E20)),"") | I20: Gas Medis | J20: m³ oksigen | M20: =IFERROR(K20+L20,"") -> 0 | S20: =IF(COUNTA(B20:C20)>COUNT(B20:C20),"CEK: ada isian bukan angka",IF(COUNT(B20:C20)=0,"KOSONG: isi kunjungan JKN dan Non-JKN (kolom B, C)",IF(COUNT(B20:C20)<2,"BELUM LENGKAP: isi B dan C (boleh 0)",IF(OR(B20<0,C20<0,B20<>INT(B20),C20<>INT(C20)),"CEK: harus bilangan bulat ≥ 0",IF(SUM(D20:E20)>0,"CEK: hari rawat hanya diisi di baris 2–6 (rawat inap)","OK"))))) -> KOSONG: isi kunjungan JKN dan Non-JKN (kolom B, C) | T20: =IF(COUNTA(K20:L20)>COUNT(K20:L20),"CEK: ada isian bukan angka",IF(COUNT(K20:L20)=0,"KOSONG: isi volume JKN (K) dan Non-JKN (L)",IF(COUNT(K20:L20)<2,"BELUM LENGKAP: isi K dan L (boleh 0)",IF(OR(K20<0,L20<0),"CEK: harus angka ≥ 0","OK")))) -> KOSONG: isi volume JKN (K) dan Non-JKN (L)
A21: Kulit dan Kelamin | F21: =IFERROR(IF(COUNT(B21:C21)<2,"",SUM(B21:C21)),"") | G21: =IFERROR(IF(COUNT(D21:E21)<2,"",SUM(D21:E21)),"") | I21: Bank Darah | J21: kantong | M21: =IFERROR(K21+L21,"") -> 0 | S21: =IF(COUNTA(B21:C21)>COUNT(B21:C21),"CEK: ada isian bukan angka",IF(COUNT(B21:C21)=0,"KOSONG: isi kunjungan JKN dan Non-JKN (kolom B, C)",IF(COUNT(B21:C21)<2,"BELUM LENGKAP: isi B dan C (boleh 0)",IF(OR(B21<0,C21<0,B21<>INT(B21),C21<>INT(C21)),"CEK: harus bilangan bulat ≥ 0",IF(SUM(D21:E21)>0,"CEK: hari rawat hanya diisi di baris 2–6 (rawat inap)","OK"))))) -> KOSONG: isi kunjungan JKN dan Non-JKN (kolom B, C) | T21: =IF(COUNTA(K21:L21)>COUNT(K21:L21),"CEK: ada isian bukan angka",IF(COUNT(K21:L21)=0,"KOSONG: isi volume JKN (K) dan Non-JKN (L)",IF(COUNT(K21:L21)<2,"BELUM LENGKAP: isi K dan L (boleh 0)",IF(OR(K21<0,L21<0,K21<>INT(K21),L21<>INT(L21)),"CEK: harus bilangan bulat ≥ 0","OK")))) -> KOSONG: isi volume JKN (K) dan Non-JKN (L)
A22: Infeksi / Penyakit Tropis | F22: =IFERROR(IF(COUNT(B22:C22)<2,"",SUM(B22:C22)),"") | G22: =IFERROR(IF(COUNT(D22:E22)<2,"",SUM(D22:E22)),"") | I22: Bank Jaringan | J22: jaringan | M22: =IFERROR(K22+L22,"") -> 0 | S22: =IF(COUNTA(B22:C22)>COUNT(B22:C22),"CEK: ada isian bukan angka",IF(COUNT(B22:C22)=0,"KOSONG: isi kunjungan JKN dan Non-JKN (kolom B, C)",IF(COUNT(B22:C22)<2,"BELUM LENGKAP: isi B dan C (boleh 0)",IF(OR(B22<0,C22<0,B22<>INT(B22),C22<>INT(C22)),"CEK: harus bilangan bulat ≥ 0",IF(SUM(D22:E22)>0,"CEK: hari rawat hanya diisi di baris 2–6 (rawat inap)","OK"))))) -> KOSONG: isi kunjungan JKN dan Non-JKN (kolom B, C) | T22: =IF(COUNTA(K22:L22)>COUNT(K22:L22),"CEK: ada isian bukan angka",IF(COUNT(K22:L22)=0,"KOSONG: isi volume JKN (K) dan Non-JKN (L)",IF(COUNT(K22:L22)<2,"BELUM LENGKAP: isi K dan L (boleh 0)",IF(OR(K22<0,L22<0,K22<>INT(K22),L22<>INT(L22)),"CEK: harus bilangan bulat ≥ 0","OK")))) -> KOSONG: isi volume JKN (K) dan Non-JKN (L)
A23: Hematologi dan Onkologi Medik | F23: =IFERROR(IF(COUNT(B23:C23)<2,"",SUM(B23:C23)),"") | G23: =IFERROR(IF(COUNT(D23:E23)<2,"",SUM(D23:E23)),"") | S23: =IF(COUNTA(B23:C23)>COUNT(B23:C23),"CEK: ada isian bukan angka",IF(COUNT(B23:C23)=0,"KOSONG: isi kunjungan JKN dan Non-JKN (kolom B, C)",IF(COUNT(B23:C23)<2,"BELUM LENGKAP: isi B dan C (boleh 0)",IF(OR(B23<0,C23<0,B23<>INT(B23),C23<>INT(C23)),"CEK: harus bilangan bulat ≥ 0",IF(SUM(D23:E23)>0,"CEK: hari rawat hanya diisi di baris 2–6 (rawat inap)","OK"))))) -> KOSONG: isi kunjungan JKN dan Non-JKN (kolom B, C)
A24: Imunologi dan Reumatologi | F24: =IFERROR(IF(COUNT(B24:C24)<2,"",SUM(B24:C24)),"") | G24: =IFERROR(IF(COUNT(D24:E24)<2,"",SUM(D24:E24)),"") | I24: Volume penunjang menjadi dasar unit cost per item (resep, tes, pemeriksaan, jam operasi). Pada simulasi ini penunjang klinis dialokasikan sebagai pool terpisah. | S24: =IF(COUNTA(B24:C24)>COUNT(B24:C24),"CEK: ada isian bukan angka",IF(COUNT(B24:C24)=0,"KOSONG: isi kunjungan JKN dan Non-JKN (kolom B, C)",IF(COUNT(B24:C24)<2,"BELUM LENGKAP: isi B dan C (boleh 0)",IF(OR(B24<0,C24<0,B24<>INT(B24),C24<>INT(C24)),"CEK: harus bilangan bulat ≥ 0",IF(SUM(D24:E24)>0,"CEK: hari rawat hanya diisi di baris 2–6 (rawat inap)","OK"))))) -> KOSONG: isi kunjungan JKN dan Non-JKN (kolom B, C)
A25: Keracunan (Toksikologi) | F25: =IFERROR(IF(COUNT(B25:C25)<2,"",SUM(B25:C25)),"") | G25: =IFERROR(IF(COUNT(D25:E25)<2,"",SUM(D25:E25)),"") | S25: =IF(COUNTA(B25:C25)>COUNT(B25:C25),"CEK: ada isian bukan angka",IF(COUNT(B25:C25)=0,"KOSONG: isi kunjungan JKN dan Non-JKN (kolom B, C)",IF(COUNT(B25:C25)<2,"BELUM LENGKAP: isi B dan C (boleh 0)",IF(OR(B25<0,C25<0,B25<>INT(B25),C25<>INT(C25)),"CEK: harus bilangan bulat ≥ 0",IF(SUM(D25:E25)>0,"CEK: hari rawat hanya diisi di baris 2–6 (rawat inap)","OK"))))) -> KOSONG: isi kunjungan JKN dan Non-JKN (kolom B, C)
A26: Endokrin, Metabolik, dan Diabetes | F26: =IFERROR(IF(COUNT(B26:C26)<2,"",SUM(B26:C26)),"") | G26: =IFERROR(IF(COUNT(D26:E26)<2,"",SUM(D26:E26)),"") | S26: =IF(COUNTA(B26:C26)>COUNT(B26:C26),"CEK: ada isian bukan angka",IF(COUNT(B26:C26)=0,"KOSONG: isi kunjungan JKN dan Non-JKN (kolom B, C)",IF(COUNT(B26:C26)<2,"BELUM LENGKAP: isi B dan C (boleh 0)",IF(OR(B26<0,C26<0,B26<>INT(B26),C26<>INT(C26)),"CEK: harus bilangan bulat ≥ 0",IF(SUM(D26:E26)>0,"CEK: hari rawat hanya diisi di baris 2–6 (rawat inap)","OK"))))) -> KOSONG: isi kunjungan JKN dan Non-JKN (kolom B, C)
A27: Luka Bakar (Burn Unit) | F27: =IFERROR(IF(COUNT(B27:C27)<2,"",SUM(B27:C27)),"") | G27: =IFERROR(IF(COUNT(D27:E27)<2,"",SUM(D27:E27)),"") | S27: =IF(COUNTA(B27:C27)>COUNT(B27:C27),"CEK: ada isian bukan angka",IF(COUNT(B27:C27)=0,"KOSONG: isi kunjungan JKN dan Non-JKN (kolom B, C)",IF(COUNT(B27:C27)<2,"BELUM LENGKAP: isi B dan C (boleh 0)",IF(OR(B27<0,C27<0,B27<>INT(B27),C27<>INT(C27)),"CEK: harus bilangan bulat ≥ 0",IF(SUM(D27:E27)>0,"CEK: hari rawat hanya diisi di baris 2–6 (rawat inap)","OK"))))) -> KOSONG: isi kunjungan JKN dan Non-JKN (kolom B, C)
A28: Jiwa / Psikiatri | F28: =IFERROR(IF(COUNT(B28:C28)<2,"",SUM(B28:C28)),"") | G28: =IFERROR(IF(COUNT(D28:E28)<2,"",SUM(D28:E28)),"") | S28: =IF(COUNTA(B28:C28)>COUNT(B28:C28),"CEK: ada isian bukan angka",IF(COUNT(B28:C28)=0,"KOSONG: isi kunjungan JKN dan Non-JKN (kolom B, C)",IF(COUNT(B28:C28)<2,"BELUM LENGKAP: isi B dan C (boleh 0)",IF(OR(B28<0,C28<0,B28<>INT(B28),C28<>INT(C28)),"CEK: harus bilangan bulat ≥ 0",IF(SUM(D28:E28)>0,"CEK: hari rawat hanya diisi di baris 2–6 (rawat inap)","OK"))))) -> KOSONG: isi kunjungan JKN dan Non-JKN (kolom B, C)
A29: Gigi dan Mulut | F29: =IFERROR(IF(COUNT(B29:C29)<2,"",SUM(B29:C29)),"") | G29: =IFERROR(IF(COUNT(D29:E29)<2,"",SUM(D29:E29)),"") | S29: =IF(COUNTA(B29:C29)>COUNT(B29:C29),"CEK: ada isian bukan angka",IF(COUNT(B29:C29)=0,"KOSONG: isi kunjungan JKN dan Non-JKN (kolom B, C)",IF(COUNT(B29:C29)<2,"BELUM LENGKAP: isi B dan C (boleh 0)",IF(OR(B29<0,C29<0,B29<>INT(B29),C29<>INT(C29)),"CEK: harus bilangan bulat ≥ 0",IF(SUM(D29:E29)>0,"CEK: hari rawat hanya diisi di baris 2–6 (rawat inap)","OK"))))) -> KOSONG: isi kunjungan JKN dan Non-JKN (kolom B, C)
A30: Forensik dan Medikolegal | F30: =IFERROR(IF(COUNT(B30:C30)<2,"",SUM(B30:C30)),"") | G30: =IFERROR(IF(COUNT(D30:E30)<2,"",SUM(D30:E30)),"") | S30: =IF(COUNTA(B30:C30)>COUNT(B30:C30),"CEK: ada isian bukan angka",IF(COUNT(B30:C30)=0,"KOSONG: isi kunjungan JKN dan Non-JKN (kolom B, C)",IF(COUNT(B30:C30)<2,"BELUM LENGKAP: isi B dan C (boleh 0)",IF(OR(B30<0,C30<0,B30<>INT(B30),C30<>INT(C30)),"CEK: harus bilangan bulat ≥ 0",IF(SUM(D30:E30)>0,"CEK: hari rawat hanya diisi di baris 2–6 (rawat inap)","OK"))))) -> KOSONG: isi kunjungan JKN dan Non-JKN (kolom B, C)
A31: Rehabilitasi Medik | F31: =IFERROR(IF(COUNT(B31:C31)<2,"",SUM(B31:C31)),"") | G31: =IFERROR(IF(COUNT(D31:E31)<2,"",SUM(D31:E31)),"") | S31: =IF(COUNTA(B31:C31)>COUNT(B31:C31),"CEK: ada isian bukan angka",IF(COUNT(B31:C31)=0,"KOSONG: isi kunjungan JKN dan Non-JKN (kolom B, C)",IF(COUNT(B31:C31)<2,"BELUM LENGKAP: isi B dan C (boleh 0)",IF(OR(B31<0,C31<0,B31<>INT(B31),C31<>INT(C31)),"CEK: harus bilangan bulat ≥ 0",IF(SUM(D31:E31)>0,"CEK: hari rawat hanya diisi di baris 2–6 (rawat inap)","OK"))))) -> KOSONG: isi kunjungan JKN dan Non-JKN (kolom B, C)
A32: TOTAL VOLUME | B32: =IFERROR(SUM(B2:B31),"") -> 0 | C32: =IFERROR(SUM(C2:C31),"") -> 0 | D32: =IFERROR(SUM(D2:D31),"") -> 0 | E32: =IFERROR(SUM(E2:E31),"") -> 0 | F32: =IFERROR(SUM(F2:F31),"") -> 0 | G32: =IFERROR(SUM(G2:G31),"") -> 0
A34: Kunjungan: rawat jalan dan IGD. Hari rawat: rawat inap. Pisahkan JKN dan Non-JKN. Kolom kosong berarti unit tidak memiliki jenis layanan itu.
A35: Pusat biaya final = 6 pusat biaya tetap + 24 layanan. Nama harus sama persis dengan Costing Template.
A36: Pasien pulang dan tempat tidur per kelas ada pada blok statistik di kanan (kolom I sampai Q).
A38: DEFINISI OPERASIONAL (DO) DAN ATURAN ISIAN SHEET INI
A39: Isian (kolom dan baris) | B39: Definisi Operasional (DO) | I39: Aturan Validasi dan Cara Mengisi
A40: Kunjungan JKN (B7:B31) IGD dan 24 layanan | B40: Jumlah kunjungan (bukan jumlah pasien unik) pasien peserta JKN selama 1 Januari sampai 31 Desember. Pasien yang datang 3 kali dihitung 3 kunjungan. | I40: Wajib untuk baris 7–31. Bilangan bulat ≥ 0, isi 0 bila tidak ada. Satu kunjungan hanya dihitung di satu layanan. Baris 2–6 dikosongkan. Total semua layanan harus sama dengan total kunjungan poliklinik RS.
A41: Kunjungan Non-JKN (C7:C31) | B41: Jumlah kunjungan pasien umum, asuransi swasta, dan penjamin lain (bukan JKN) selama setahun. | I41: Sama dengan kunjungan JKN. Jumlah JKN + Non-JKN harus cocok dengan laporan SIMRS.
A42: Hari Rawat JKN (D2:D6) | B42: Jumlah hari pasien JKN menempati tempat tidur selama setahun. Pasien yang masuk dan pulang pada hari yang sama dihitung 1 hari. | I42: Wajib untuk baris 2–6 (KRIS C, B, A, VIP, ICU). Bilangan bulat ≥ 0. Tidak boleh melebihi tempat tidur × 365. Baris 7–31 dikosongkan agar tidak terhitung ganda.
...

Sheet Data LO Lapkeu
A1: LAPORAN OPERASIONAL (LO) TAHUN DATA (RUPIAH) | B1: Realisasi (Rp) | C1: Keterangan | D1: Definisi Operasional (DO) | E1: Aturan Validasi Isian | F1: Hasil Pemeriksaan
A2: I. PENDAPATAN OPERASIONAL
A3: Pendapatan Alokasi APBN | C3: Pendanaan pemerintah. | D3: Pendapatan dari alokasi APBN yang diakui pada LO tahun data. | E3: Wajib. Rupiah penuh, angka ≥ 0, tanpa titik, koma, atau Rp. Isi 0 bila tidak ada. Salin apa adanya dari LO. | F3: =IF(B3="","KOSONG: isi 0 bila tidak ada",IF(AND(ISNUMBER(B3),B3>=0),"OK","CEK: harus angka ≥ 0")) -> KOSONG: isi 0 bila tidak ada
A4: Pendapatan Jasa Layanan dari Masyarakat | C4: Pasien JKN dan umum. | D4: Pendapatan jasa layanan dari pasien/masyarakat (JKN dan umum) pada LO tahun data. | E4: Wajib. Rupiah penuh, angka ≥ 0, tanpa titik, koma, atau Rp. Isi 0 bila tidak ada. Salin apa adanya dari LO. | F4: =IF(B4="","KOSONG: isi 0 bila tidak ada",IF(AND(ISNUMBER(B4),B4>=0),"OK","CEK: harus angka ≥ 0")) -> KOSONG: isi 0 bila tidak ada
A5: Pendapatan Jasa Layanan dari Entitas Lain | C5: Asuransi dan penjamin lain. | D5: Pendapatan jasa layanan dari asuransi dan penjamin lain pada LO tahun data. | E5: Wajib. Rupiah penuh, angka ≥ 0, tanpa titik, koma, atau Rp. Isi 0 bila tidak ada. Salin apa adanya dari LO. | F5: =IF(B5="","KOSONG: isi 0 bila tidak ada",IF(AND(ISNUMBER(B5),B5>=0),"OK","CEK: harus angka ≥ 0")) -> KOSONG: isi 0 bila tidak ada
A6: Pendapatan Hibah BLU | C6: Pendanaan pemerintah. | D6: Pendapatan hibah yang diterima BLU (uang, barang, atau jasa) pada LO tahun data. | E6: Wajib. Rupiah penuh, angka ≥ 0, tanpa titik, koma, atau Rp. Isi 0 bila tidak ada. Salin apa adanya dari LO. | F6: =IF(B6="","KOSONG: isi 0 bila tidak ada",IF(AND(ISNUMBER(B6),B6>=0),"OK","CEK: harus angka ≥ 0")) -> KOSONG: isi 0 bila tidak ada
A7: Pendapatan Hasil Kerja Sama BLU | D7: Pendapatan hasil kerja sama BLU dengan pihak lain pada LO tahun data. | E7: Wajib. Rupiah penuh, angka ≥ 0, tanpa titik, koma, atau Rp. Isi 0 bila tidak ada. Salin apa adanya dari LO. | F7: =IF(B7="","KOSONG: isi 0 bila tidak ada",IF(AND(ISNUMBER(B7),B7>=0),"OK","CEK: harus angka ≥ 0")) -> KOSONG: isi 0 bila tidak ada
A8: Pendapatan BLU Lainnya | C8: Sewa, parkir, dan lain-lain. | D8: Pendapatan BLU lainnya, misalnya sewa dan parkir, pada LO tahun data. | E8: Wajib. Rupiah penuh, angka ≥ 0, tanpa titik, koma, atau Rp. Isi 0 bila tidak ada. Salin apa adanya dari LO. | F8: =IF(B8="","KOSONG: isi 0 bila tidak ada",IF(AND(ISNUMBER(B8),B8>=0),"OK","CEK: harus angka ≥ 0")) -> KOSONG: isi 0 bila tidak ada
A9: JUMLAH PENDAPATAN | B9: =IFERROR(SUM(B3:B8),"") -> 0 | C9: Otomatis. | D9: Total pendapatan = baris 3 sampai 8. | E9: Otomatis (terkunci). Jangan diisi.
A10: II. BEBAN OPERASIONAL
A11: Beban Pegawai | C11: Gaji, tunjangan, jasa pelayanan, dan remunerasi. | D11: Beban pegawai pada LO: gaji, tunjangan, jasa pelayanan, remunerasi. | E11: Wajib. Rupiah penuh, angka ≥ 0, tanpa titik, koma, atau Rp. Isi 0 bila tidak ada. Salin apa adanya dari LO. | F11: =IF(B11="","KOSONG: isi 0 bila tidak ada",IF(AND(ISNUMBER(B11),B11>=0),"OK","CEK: harus angka ≥ 0")) -> KOSONG: isi 0 bila tidak ada
A12: Beban Persediaan | C12: Obat, BMHP, reagen, bahan makanan. | D12: Beban persediaan pada LO: obat, BMHP, reagen, bahan makanan. | E12: Wajib. Rupiah penuh, angka ≥ 0, tanpa titik, koma, atau Rp. Isi 0 bila tidak ada. Salin apa adanya dari LO. | F12: =IF(B12="","KOSONG: isi 0 bila tidak ada",IF(AND(ISNUMBER(B12),B12>=0),"OK","CEK: harus angka ≥ 0")) -> KOSONG: isi 0 bila tidak ada
A13: Beban Barang dan Jasa | C13: Listrik, air, jasa pihak ketiga. | D13: Beban barang dan jasa pada LO: listrik, air, jasa pihak ketiga. | E13: Wajib. Rupiah penuh, angka ≥ 0, tanpa titik, koma, atau Rp. Isi 0 bila tidak ada. Salin apa adanya dari LO. | F13: =IF(B13="","KOSONG: isi 0 bila tidak ada",IF(AND(ISNUMBER(B13),B13>=0),"OK","CEK: harus angka ≥ 0")) -> KOSONG: isi 0 bila tidak ada
A14: Beban Pemeliharaan | D14: Beban pemeliharaan alat, gedung, dan sarana pada LO. | E14: Wajib. Rupiah penuh, angka ≥ 0, tanpa titik, koma, atau Rp. Isi 0 bila tidak ada. Salin apa adanya dari LO. | F14: =IF(B14="","KOSONG: isi 0 bila tidak ada",IF(AND(ISNUMBER(B14),B14>=0),"OK","CEK: harus angka ≥ 0")) -> KOSONG: isi 0 bila tidak ada
A15: Beban Perjalanan Dinas | D15: Beban perjalanan dinas pada LO. | E15: Wajib. Rupiah penuh, angka ≥ 0, tanpa titik, koma, atau Rp. Isi 0 bila tidak ada. Salin apa adanya dari LO. | F15: =IF(B15="","KOSONG: isi 0 bila tidak ada",IF(AND(ISNUMBER(B15),B15>=0),"OK","CEK: harus angka ≥ 0")) -> KOSONG: isi 0 bila tidak ada
A16: Beban Penyusutan dan Amortisasi | D16: Beban penyusutan dan amortisasi aset pada LO. | E16: Wajib. Rupiah penuh, angka ≥ 0, tanpa titik, koma, atau Rp. Isi 0 bila tidak ada. Salin apa adanya dari LO. | F16: =IF(B16="","KOSONG: isi 0 bila tidak ada",IF(AND(ISNUMBER(B16),B16>=0),"OK","CEK: harus angka ≥ 0")) -> KOSONG: isi 0 bila tidak ada
A17: Beban Penyisihan Piutang Tak Tertagih | D17: Beban penyisihan piutang tak tertagih pada LO. | E17: Wajib. Rupiah penuh, angka ≥ 0, tanpa titik, koma, atau Rp. Isi 0 bila tidak ada. Salin apa adanya dari LO. | F17: =IF(B17="","KOSONG: isi 0 bila tidak ada",IF(AND(ISNUMBER(B17),B17>=0),"OK","CEK: harus angka ≥ 0")) -> KOSONG: isi 0 bila tidak ada
A18: JUMLAH BEBAN OPERASIONAL | B18: =IFERROR(SUM(B11:B17),"") -> 0 | C18: Otomatis. | D18: Total beban operasional = baris 11 sampai 17. | E18: Otomatis (terkunci). Jangan diisi.
A19: SURPLUS (DEFISIT) DARI KEGIATAN OPERASIONAL | B19: =IFERROR(B9-B18,"") -> 0 | C19: Otomatis. | D19: Pendapatan dikurangi beban operasional. | E19: Otomatis (terkunci). Jangan diisi.
A20: Surplus/Defisit Pelepasan Aset Non Lancar | C20: Pendapatan pelepasan aset dikurangi beban pelepasan aset. Isi negatif jika defisit. | D20: Pendapatan pelepasan aset non lancar dikurangi bebannya. Hasil bersih surplus atau defisit. | E20: Wajib. Rupiah penuh tanpa titik, koma, atau Rp. Boleh negatif bila defisit (tulis dengan tanda minus). Isi 0 bila tidak ada. | F20: =IF(B20="","KOSONG: isi 0 bila tidak ada",IF(ISNUMBER(B20),"OK","CEK: harus angka")) -> KOSONG: isi 0 bila tidak ada
A21: Surplus/Defisit Kegiatan Non Operasional Lainnya | C21: Pendapatan dikurangi beban kegiatan non operasional lainnya. Isi negatif jika defisit. | D21: Pendapatan non operasional lainnya dikurangi bebannya. Hasil bersih surplus atau defisit. | E21: Wajib. Rupiah penuh tanpa titik, koma, atau Rp. Boleh negatif bila defisit (tulis dengan tanda minus). Isi 0 bila tidak ada. | F21: =IF(B21="","KOSONG: isi 0 bila tidak ada",IF(ISNUMBER(B21),"OK","CEK: harus angka")) -> KOSONG: isi 0 bila tidak ada
A22: JUMLAH SURPLUS (DEFISIT) KEGIATAN NON OPERASIONAL | B22: =IFERROR(B20+B21,"") -> 0 | C22: Otomatis. | D22: Jumlah surplus (defisit) kegiatan non operasional. | E22: Otomatis (terkunci). Jangan diisi.
A23: SURPLUS (DEFISIT) LO | B23: =IFERROR(B19+B22,"") -> 0 | C23: Otomatis. | D23: Surplus (defisit) LO hasil hitungan template. | E23: Otomatis (terkunci). Jangan diisi.
A24: Surplus (Defisit) LO sesuai laporan | C24: Angka pada laporan resmi. | D24: Angka surplus (defisit) LO pada laporan resmi, dipakai untuk menguji hitungan template. | E24: Wajib. Rupiah penuh tanpa titik, koma, atau Rp. Boleh negatif bila defisit (tulis dengan tanda minus). Isi 0 bila tidak ada. Selisih dengan B23 harus 0. | F24: =IF(B24="","KOSONG: isi angka laporan",IF(NOT(ISNUMBER(B24)),"CEK: harus angka",IF(ABS(N(B25))<=1000,"OK","CEK: beda dengan hitungan B23, periksa baris 3-21"))) -> KOSONG: isi angka laporan
A25: Selisih (harus 0) | B25: =IFERROR(B23-B24,"") -> 0 | C25: Otomatis. | D25: Selisih surplus (defisit) hitungan dan laporan. Harus 0. | E25: Otomatis (terkunci). Jangan diisi. | F25: =IF(B25="","Menunggu: data",IF(ABS(B25)<=1000,"OK","CEK: selisih tidak 0")) -> OK
A26: III. RINCIAN BEBAN UNTUK COSTING
A27: Biaya Gaji | C27: Masuk kolom Biaya Gaji di Costing Template. | D27: Gaji pokok dan tunjangan pegawai setahun. Tidak termasuk jasa pelayanan. | E27: Wajib. Rupiah penuh, angka ≥ 0, tanpa titik, koma, atau Rp. Isi 0 bila tidak ada. Salin apa adanya dari LO. Harus sama dengan total kolom Biaya Gaji di Costing Template. | F27: =IF(B27="","KOSONG: isi 0 bila tidak ada",IF(NOT(AND(ISNUMBER(B27),B27>=0)),"CEK: harus angka ≥ 0",IF(N('Costing Template'!S69)=0,"OK",IF(ABS(N(B43))>1000,"CEK: beda dengan total kolom Costing Template (lihat B43)","OK")))) -> KOSONG: isi 0 bila tidak ada
A28: Biaya Jasa Medis/Remunerasi Dokter | C28: Masuk kolom Biaya Jasa Medis. | D28: Jasa pelayanan dan remunerasi dokter setahun. | E28: Wajib. Rupiah penuh, angka ≥ 0, tanpa titik, koma, atau Rp. Isi 0 bila tidak ada. Salin apa adanya dari LO. Harus sama dengan total kolom Biaya Jasa Medis di Costing Template. | F28: =IF(B28="","KOSONG: isi 0 bila tidak ada",IF(NOT(AND(ISNUMBER(B28),B28>=0)),"CEK: harus angka ≥ 0",IF(N('Costing Template'!S69)=0,"OK",IF(ABS(N(B44))>1000,"CEK: beda dengan total kolom Costing Template (lihat B44)","OK")))) -> KOSONG: isi 0 bila tidak ada
A29: Biaya Jasa Lainnya/Remunerasi Staf | C29: Masuk kolom Biaya Jasa Medis Lain. | D29: Jasa pelayanan dan remunerasi perawat dan staf lain setahun. | E29: Wajib. Rupiah penuh, angka ≥ 0, tanpa titik, koma, atau Rp. Isi 0 bila tidak ada. Salin apa adanya dari LO. Harus sama dengan total kolom Biaya Jasa Medis Lain di Costing Template. | F29: =IF(B29="","KOSONG: isi 0 bila tidak ada",IF(NOT(AND(ISNUMBER(B29),B29>=0)),"CEK: harus angka ≥ 0",IF(N('Costing Template'!S69)=0,"OK",IF(ABS(N(B45))>1000,"CEK: beda dengan total kolom Costing Template (lihat B45)","OK")))) -> KOSONG: isi 0 bila tidak ada
A30: Biaya Operasional Lainnya | C30: Persediaan, barang dan jasa, pemeliharaan, perjalanan dinas, piutang, dan pegawai lainnya. | D30: Seluruh biaya di luar gaji, jasa, dan penyusutan: persediaan, barang dan jasa, pemeliharaan, perjalanan dinas, piutang, dan beban pegawai lainnya. | E30: Wajib. Rupiah penuh, angka ≥ 0, tanpa titik, koma, atau Rp. Isi 0 bila tidak ada. Salin apa adanya dari LO. Harus sama dengan total Biaya Operasional di Costing Template. | F30: =IF(B30="","KOSONG: isi 0 bila tidak ada",IF(NOT(AND(ISNUMBER(B30),B30>=0)),"CEK: harus angka ≥ 0",IF(N('Costing Template'!S69)=0,"OK",IF(ABS(N(B46))>1000,"CEK: beda dengan total kolom Costing Template (lihat B46)","OK")))) -> KOSONG: isi 0 bila tidak ada
A31: Penyusutan Investasi (Alat Medik dan Non Medik) | C31: Nilai alat ÷ 5 tahun. | D31: Penyusutan alat medik dan non medik setahun = nilai perolehan alat ÷ 5 tahun. | E31: Wajib. Rupiah penuh, angka ≥ 0, tanpa titik, koma, atau Rp. Isi 0 bila tidak ada. Salin apa adanya dari LO. Harus sama dengan total Dep. Peralatan di Costing Template. | F31: =IF(B31="","KOSONG: isi 0 bila tidak ada",IF(NOT(AND(ISNUMBER(B31),B31>=0)),"CEK: harus angka ≥ 0",IF(N('Costing Template'!S69)=0,"OK",IF(ABS(N(B47))>1000,"CEK: beda dengan total kolom Costing Template (lihat B47)","OK")))) -> KOSONG: isi 0 bila tidak ada
A32: Penyusutan Gedung | C32: Investasi gedung ÷ 40 tahun. | D32: Penyusutan gedung setahun = nilai perolehan gedung ÷ 40 tahun. | E32: Wajib. Rupiah penuh, angka ≥ 0, tanpa titik, koma, atau Rp. Isi 0 bila tidak ada. Salin apa adanya dari LO. Harus sama dengan total Dep. Gedung di Costing Template. | F32: =IF(B32="","KOSONG: isi 0 bila tidak ada",IF(NOT(AND(ISNUMBER(B32),B32>=0)),"CEK: harus angka ≥ 0",IF(N('Costing Template'!S69)=0,"OK",IF(ABS(N(B48))>1000,"CEK: beda dengan total kolom Costing Template (lihat B48)","OK")))) -> KOSONG: isi 0 bila tidak ada
A33: TOTAL BIAYA RUMAH SAKIT | B33: =IFERROR(SUM(B27:B32),"") -> 0 | C33: Otomatis. | D33: Total biaya RS untuk costing = baris 27 sampai 32. | E33: Otomatis (terkunci). Jangan diisi.
A34: Selisih terhadap jumlah beban LO (harus 0) | B34: =IFERROR(B33-B18,"") -> 0 | C34: Otomatis. | D34: Total biaya costing dikurangi total beban LO. Harus 0. | E34: Otomatis (terkunci). Jangan diisi. | F34: =IF(B34="","Menunggu: data",IF(ABS(B34)<=1000,"OK","CEK: selisih tidak 0")) -> OK
A35: IV. PEMBAGIAN PENDAPATAN
A36: Pendapatan Fungsional JKN | C36: Dari klaim JKN. | D36: Pendapatan klaim JKN (BPJS) yang diterima RS pada tahun data. | E36: Wajib. Rupiah penuh, angka ≥ 0, tanpa titik, koma, atau Rp. Isi 0 bila tidak ada. Salin apa adanya dari LO. Tidak boleh lebih besar dari B4 + B5. | F36: =IF(B36="","KOSONG: isi 0 bila tidak ada",IF(NOT(AND(ISNUMBER(B36),B36>=0)),"CEK: harus angka ≥ 0",IF(B36>N(B4)+N(B5),"CEK: melebihi pendapatan jasa layanan (B4+B5)","OK"))) -> KOSONG: isi 0 bila tidak ada
